Workbook

Sheet Raw_Inflation
A1: Data Source | B1: World Development Indicators
A3: Last Updated Date | B3: 2026-10-08
A5: Country Name | B5: Country Code | C5: Indicator Name | D5: Indicator Code | E5: 1960 | F5: 1961 | G5: 1962 | H5: 1963 | I5: 1964 | J5: 1965 | K5: 1966 | L5: 1967 | M5: 1968 | N5: 1969 | O5: 1970 | P5: 1971 | Q5: 1972 | R5: 1973 | S5: 1974 | T5: 1975 | U5: 1976 | V5: 1977 | W5: 1978 | X5: 1979 | Y5: 1980 | Z5: 1981 | AA5: 1982 | AB5: 1983 | AC5: 1984 | AD5: 1985 | AE5: 1986 | AF5: 1987 | AG5: 1988 | AH5: 1989 | AI5: 1990 | AJ5: 1991 | AK5: 1992 | AL5: 1993 | AM5: 1994 | AN5: 1995 | AO5: 1996 | AP5: 1997 | AQ5: 1998 | AR5: 1999 | AS5: 2000 | AT5: 2001 | AU5: 2002 | AV5: 2003 | AW5: 2004 | AX5: 2005 | AY5: 2006 | AZ5: 2007 | BA5: 2008 | BB5: 2009 | BC5: 2010 | BD5: 2011 | BE5: 2012 | BF5: 2013 | BG5: 2014 | BH5: 2015 | BI5: 2016 | BJ5: 2017 | BK5: 2018 | BL5: 2019 | BM5: 2020 | BN5: 2021 | BO5: 2022 | BP5: 2023 | BQ5: 2024 | BR5: 2025
A6: Aruba | B6: ABW | C6: Inflation, consumer prices (annual %) | D6: FP.CPI.TOTL.ZG | AD6: 4.0322581 | AE6: 1.0739664 | AF6: 3.6430455 | AG6: 3.1218685 | AH6: 3.991628 | AI6: 5.8366878 | AJ6: 5.5555556 | AK6: 3.8733754 | AL6: 5.21556 | AM6: 6.3110797 | AN6: 3.3613911 | AO6: 3.225288 | AP6: 2.9999481 | AQ6: 1.8694885 | AR6: 2.280372 | AS6: 4.0440213 | AT6: 2.8836043 | AU6: 3.3152468 | AV6: 3.6563651 | AW6: 2.5291295 | AX6: 3.3977868 | AY6: 3.6080244 | AZ6: 5.3925678 | BA6: 8.9559871 | BB6: -2.1354287 | BC6: 2.0781407 | BD6: 4.3162974 | BE6: 0.62747199 | BF6: -2.3720652 | BG6: 0.42144092 | BH6: 0.4747636 | BI6: -0.93119599 | BJ6: -1.0282818 | BK6: 3.6260414 | BL6: 4.257462
A7: Africa Eastern and Southern | B7: AFE | C7: Inflation, consumer prices (annual %) | D7: FP.CPI.TOTL.ZG | S7: 19.598394 | T7: 15.224099 | U7: 11.216481 | V7: 14.238055 | W7: 12.526893 | X7: 15.06985 | Y7: 15.066512 | Z7: 14.461591 | AA7: 12.139918 | AB7: 11.567524 | AC7: 10.983863 | AD7: 13.006566 | AE7: 13.891972 | AF7: 12.563443 | AG7: 12.522258 | AH7: 12.558202 | AI7: 12.457914 | AJ7: 17.6781 | AK7: 16.167612 | AL7: 13.135661 | AM7: 14.852815 | AN7: 12.288591 | AO7: 9.7065863 | AP7: 10.249599 | AQ7: 7.4952554 | AR7: 7.8198648 | AS7: 8.6014851 | AT7: 5.840354 | AU7: 8.7637552 | AV7: 7.4497001 | AW7: 5.0234207 | AX7: 8.558038 | AY7: 8.8981638 | AZ7: 8.4507748 | BA7: 12.566645 | BB7: 8.954218 | BC7: 5.5375379 | BD7: 8.9712064 | BE7: 9.1587084 | BF7: 5.7488313 | BG7: 5.5258192 | BH7: 5.0985616 | BI7: 6.4468772 | BJ7: 6.2213753 | BK7: 4.6898065 | BL7: 4.1028508 | BM7: 5.1916294 | BN7: 6.8247271 | BO7: 10.883478 | BP7: 7.3991856 | BQ7: 4.7708573 | BR7: 4.2701114
A8: Afghanistan | B8: AFG | C8: Inflation, consumer prices (annual %) | D8: FP.CPI.TOTL.ZG | AX8: 12.686269 | AY8: 6.7845966 | AZ8: 8.6805708 | BA8: 26.418664 | BB8: -6.8111611 | BC8: 2.1785375 | BD8: 11.804186 | BE8: 6.4412128 | BF8: 7.3857718 | BG8: 4.673996 | BH8: -0.66170916 | BI8: 4.383892 | BJ8: 4.9759515 | BK8: 0.62614915 | BL8: 2.3023725 | BM8: 5.6018879 | BN8: 5.1332034 | BO8: 13.712102 | BP8: -4.6447087 | BQ8: -6.6011856
A9: Africa Western and Central | B9: AFW | C9: Inflation, consumer prices (annual %) | D9: FP.CPI.TOTL.ZG | Z9: 8.7992108 | AA9: 12.059765 | AB9: 10.671937 | AC9: 11.25 | AD9: 7.3549258 | AE9: 5.950965 | AF9: 0.24878856 | AG9: 2.5236593 | AH9: 0.86928702 | AI9: 1.0573614 | AJ9: 1.7418879 | AK9: -0.062999006 | AL9: 0.55345572 | AM9: 31.841017 | AN9: 10.563289 | AO9: 4.9142397 | AP9: 3.9971417 | AQ9: 4.4711254 | AR9: 0.37226617 | AS9: 2.5307752 | AT9: 4.3615291 | AU9: 3.1886933 | AV9: 1.7609041 | AW9: 0.69433631 | AX9: 5.6316335 | AY9: 4.4158998 | AZ9: 3.6073677 | BA9: 8.4529762 | BB9: 3.2824404 | BC9: 1.7848442 | BD9: 4.0186991 | BE9: 4.5783746 | BF9: 2.4392008 | BG9: 1.7684358 | BH9: 2.1308174 | BI9: 1.4874155 | BJ9: 1.725486 | BK9: 1.7840499 | BL9: 1.9830923 | BM9: 2.4903778 | BN9: 3.7455678 | BO9: 7.9492514 | BP9: 5.221168 | BQ9: 3.6080443 | BR9: 1.6578177
A10: Angola | B10: AGO | C10: Inflation, consumer prices (annual %) | D10: FP.CPI.TOTL.ZG | AJ10: 83.783784 | AK10: 299.5098 | AL10: 1378.5276 | AM10: 949.79253 | AN10: 2666.4506 | AO10: 4145.106 | AP10: 219.17672 | AQ10: 107.28482 | AR10: 248.1959 | AS10: 324.99687 | AT10: 152.56102 | AU10: 108.89744 | AV10: 98.224144 | AW10: 43.542107 | AX10: 22.953514 | AY10: 13.30521 | AZ10: 12.251497 | BA10: 12.475829 | BB10: 13.730284 | BC10: 14.469656 | BD10: 13.482468 | BE10: 10.277905 | BF10: 8.7778143 | BG10: 7.2803873 | BH10: 9.3559722 | BI10: 30.694415 | BJ10: 29.84448 | BK10: 19.628938 | BL10: 17.080954 | BM10: 22.271539 | BN10: 25.754295 | BO10: 21.35529 | BP10: 13.644102 | BQ10: 28.240495 | BR10: 20.16202
A11: Albania | B11: ALB | C11: Inflation, consumer prices (annual %) | D11: FP.CPI.TOTL.ZG | AK11: 226.00542 | AL11: 85.004751 | AM11: 22.565053 | AN11: 7.7932185 | AO11: 12.725478 | AP11: 33.180274 | AQ11: 20.642859 | AR11: 0.38943765 | AS11: 0.050018136 | AT11: 3.1075883 | AU11: 7.7705258 | AV11: 0.48400261 | AW11: 2.2800192 | AX11: 2.366582 | AY11: 2.3707283 | AZ11: 2.9326825 | BA11: 3.3208709 | BB11: 2.2669221 | BC11: 3.6271009 | BD11: 3.4280713 | BE11: 2.0315927 | BF11: 1.9376208 | BG11: 1.625865 | BH11: 1.896174 | BI11: 1.2754317 | BJ11: 1.9866613 | BK11: 2.0280596 | BL11: 1.4110908 | BM11: 1.6208866 | BN11: 2.0414716 | BO11: 6.7252027 | BP11: 4.7583456 | BQ11: 2.2158738 | BR11: 2.1461855
A12: Andorra | B12: AND | C12: Inflation, consumer prices (annual %) | D12: FP.CPI.TOTL.ZG
A13: Arab World | B13: ARB | C13: Inflation, consumer prices (annual %) | D13: FP.CPI.TOTL.ZG | R13: 8.2666667 | S13: 15.528282 | T13: 9.6696955 | U13: 10.317416 | V13: 11.989283 | W13: 9.7160327 | Y13: 9.6260566 | Z13: 10.758503 | AA13: 8.3312558 | AB13: 5.4936655 | AC13: 8.116398 | AD13: 7.2543618 | AE13: 6.7988584 | AF13: 4.2224167 | AG13: 5.911545 | AH13: 7.740886 | AI13: 8.4514624 | AJ13: 9 | AK13: 9.3597516 | AL13: 9.3703442 | AM13: 5.1125989 | AN13: 6.5437907 | AO13: 4.6813062 | AP13: 3.601161 | AQ13: 3.4173195 | AR13: 2.6693737 | AS13: 1.8537904 | AT13: 1.7722044 | AU13: 1.8329939 | AV13: 2.7125925 | AW13: 3.63228 | AX13: 3.4936853 | AY13: 3.5449859 | AZ13: 4.7439064 | BA13: 11.270665 | BB13: 2.9208971 | BC13: 3.911062 | BD13: 4.7531639 | BE13: 4.6118443 | BF13: 3.2219776 | BG13: 2.8994791 | BH13: 1.8313523 | BI13: 2.5395604 | BJ13: 2.0693293 | BK13: 2.3124301 | BL13: 1.3360157 | BM13: 1.4470366 | BN13: 2.8683303 | BO13: 5.1722209 | BP13: 4.0002588 | BQ13: 2.3089006 | BR13: 1.7664649
A14: United Arab Emirates | B14: ARE | C14: Inflation, consumer prices (annual %) | D14: FP.CPI.TOTL.ZG | BA14: 12.25042 | BB14: 1.5618132 | BC14: 0.87798329 | BD14: 0.8773466 | BE14: 0.6622689 | BF14: 1.1011184 | BG14: 2.3462687 | BH14: 4.0699661 | BI14: 1.6174881 | BJ14: 1.9668256 | BK14: 3.0686338 | BL14: -1.9310811 | BM14: -2.0794032 | BN14: 0.17993534 | BO14: 5.291226 | BP14: 1.6267084 | BQ14: 1.6633651 | BR14: 1.2508652
A15: Argentina | B15: ARG | C15: Inflation, consumer prices (annual %) | D15: FP.CPI.TOTL.ZG | BK15: 34.277224 | BL15: 53.548304 | BM15: 42.015095 | BN15: 48.409379 | BO15: 72.430758 | BP15: 133.48894 | BQ15: 219.88393
A16: Armenia | B16: ARM | C16: Inflation, consumer prices (annual %) | D16: FP.CPI.TOTL.ZG | AM16: 3373.7594 | AN16: 175.95133 | AO16: 18.681186 | AP16: 13.960764 | AQ16: 8.6724863 | AR16: 0.64824576 | AS16: -0.79088377 | AT16: 3.1459046 | AU16: 1.0600493 | AV16: 4.7215534 | AW16: 6.9612614 | AX16: 0.638928 | AY16: 2.8923566 | AZ16: 4.4073609 | BA16: 8.9499534 | BB16: 3.4067668 | BC16: 8.1763614 | BD16: 7.6500081 | BE16: 2.5580201 | BF16: 5.7896678 | BG16: 2.9813087 | BH16: 3.7316912 | BI16: -1.4036076 | BJ16: 0.96955327 | BK16: 2.5202338 | BL16: 1.4434466 | BM16: 1.2114358 | BN16: 7.1848363 | BO16: 8.6409111 | BP16: 1.9804188 | BQ16: 0.26951198 | BR16: 3.3069334
A17: American Samoa | B17: ASM | C17: Inflation, consumer prices (annual %) | D17: FP.CPI.TOTL.ZG
A18: Antigua and Barbuda | B18: ATG | C18: Inflation, consumer prices (annual %) | D18: FP.CPI.TOTL.ZG | AR18: 1.1212879 | AS18: 0.7717798 | AT18: 1.4027966 | AU18: 2.407658 | AV18: 1.9935306 | AW18: 2.0300776 | AX18: 2.098752 | AY18: 1.7877854 | AZ18: 1.4160526 | BA18: 5.3338064 | BB18: -0.55016 | BC18: 3.3700254 | BD18: 3.4567497 | BE18: 3.3768804 | BF18: 1.0594978 | BG18: 1.0894416 | BH18: 0.96899346 | BI18: -0.4894378 | BJ18: 2.4324879 | BK18: 1.2071579 | BL18: 1.431356 | BM18: 0.62598971 | BN18: 2.0629964 | BO18: 7.5310783 | BP18: 5.0671387 | BQ18: 6.198867 | BR18: 1.3687353
A19: Australia | B19: AUS | C19: Inflation, consumer prices (annual %) | D19: FP.CPI.TOTL.ZG | E19: 3.7288215 | F19: 2.2875804 | G19: -0.31948864 | H19: 0.64102529 | I19: 2.8662267 | J19: 3.4055848 | K19: 3.2934115 | L19: 3.4782591 | M19: 2.5210072 | N19: 3.278687 | O19: 3.4391519 | P19: 6.1381084 | Q19: 6.0241041 | R19: 9.0909043 | S19: 15.416677 | T19: 15.16242 | U19: 13.322903 | V19: 12.309827 | W19: 8.0049044 | X19: 9.1220206 | Y19: 10.135849 | Z19: 9.4876614 | AA19: 11.351832 | AB19: 10.0389 | AC19: 3.9604084 | AD19: 6.734686 | AE19: 9.0503532 | AF19: 8.5330036 | AG19: 7.2159572 | AH19: 7.5338985 | AI19: 7.3330237 | AJ19: 3.1766687 | AK19: 1.0122282 | AL19: 1.7536575 | AM19: 1.9696351 | AN19: 4.6277645 | AO19: 2.615379 | AP19: 0.22489503 | AQ19: 0.86012992 | AR19: 1.4831395 | AS19: 4.4574371 | AT19: 4.40713 | AU19: 2.9815712 | AV19: 2.7325975 | AW19: 2.3432569 | AX19: 2.6918295 | AY19: 3.555287 | AZ19: 2.3276144 | BA19: 4.3502973 | BB19: 1.7711203 | BC19: 2.918337 | BD19: 3.3038478 | BE19: 1.762783 | BF19: 2.4498825 | BG19: 2.4879293 | BH19: 1.508368 | BI19: 1.2769937 | BJ19: 1.9486431 | BK19: 1.9114 | BL19: 1.6107709 | BM19: 0.84690073 | BN19: 2.8639128 | BO19: 6.5940966 | BP19: 5.5970179 | BQ19: 3.1665667 | BR19: 2.8740379
A20: Austria | B20: AUT | C20: Inflation, consumer prices (annual %) | D20: FP.CPI.TOTL.ZG | E20: 1.9457494 | F20: 3.5422399 | G20: 4.3817986 | H20: 2.708767 | I20: 3.8685635 | J20: 4.9309164 | K20: 2.0548206 | L20: 3.9746729 | M20: 2.7648645 | N20: 3.0804042 | O20: 4.3728244 | P20: 4.7042581 | Q20: 6.3551461 | R20: 7.531078 | S20: 9.5217882 | T20: 8.4452586 | U20: 7.3186855 | V20: 5.4946157 | W20: 3.5743186 | X20: 3.707401 | Y20: 6.3283254 | Z20: 6.8030418 | AA20: 5.4360308 | AB20: 3.3391645 | AC20: 5.6631857 | AD20: 3.1895168 | AE20: 1.7054446 | AF20: 1.4019527 | AG20: 1.9157168 | AH20: 2.5683483 | AI20: 3.2618723 | AJ20: 3.337427 | AK20: 4.0208478 | AL20: 3.6317852 | AM20: 2.9534094 | AN20: 2.2433663 | AO20: 1.8609712 | AP20: 1.3059786 | AQ20: 0.9224672 | AR20: 0.56899377 | AS20: 2.3448629 | AT20: 2.6500008 | AU20: 1.8103579 | AV20: 1.3555537 | AW20: 2.0612062 | AX20: 2.2991379 | AY20: 1.4415485 | AZ20: 2.1685553 | BA20: 3.2159503 | BB20: 0.50630883 | BC20: 1.8135344 | BD20: 3.2865791 | BE20: 2.4856756 | BF20: 2.0001562 | BG20: 1.6058118 | BH20: 0.89656334 | BI20: 0.89159175 | BJ20: 2.0812691 | BK20: 1.9983798 | BL20: 1.5308956 | BM20: 1.3819106 | BN20: 2.7666667 | BO20: 8.5468699 | BP20: 7.8141342 | BQ20: 2.9379157 | BR20: 3.5271944
A21: Azerbaijan | B21: AZE | C21: Inflation, consumer prices (annual %) | D21: FP.CPI.TOTL.ZG | AK21: -10.630097 | AL21: 1128 | AM21: 1662.2159 | AN21: 411.75964 | AO21: 19.794803 | AP21: 3.6743481 | AQ21: -0.77269789 | AR21: -8.52517 | AS21: 1.805003 | AT21: 1.5471959 | AU21: 2.7711647 | AV21: 2.2338649 | AW21: 6.7089304 | AX21: 9.6795073 | AY21: 8.3289248 | AZ21: 16.699755 | BA21: 20.849087 | BB21: 1.4570484 | BC21: 5.7268722 | BD21: 7.8583333 | BE21: 1.0662134 | BF21: 2.4157175 | BG21: 1.3734418 | BH21: 4.0276857 | BI21: 12.443375 | BJ21: 12.935918 | BK21: 2.2685469 | BL21: 2.6105718 | BM21: 2.7598095 | BN21: 6.6502991 | BO21: 13.852259 | BP21: 8.7854305 | BQ21: 2.2121719 | BR21: 5.6220879
A22: Burundi | B22: BDI | C22: Inflation, consumer prices (annual %) | D22: FP.CPI.TOTL.ZG | K22: 4.4368601 | L22: -1.0893246 | M22: 6.0572687 | N22: 4.0238837 | O22: -0.19965061 | P22: 3.8509627 | Q22: 3.8285577 | R22: 6.0064935 | S22: 15.722307 | T22: 15.709875 | U22: 6.8565516 | V22: 6.834514 | W22: 23.895621 | X22: 36.540757 | Y22: 2.4985195 | Z22: 12.167394 | AA22: 5.8680964 | AB22: 8.1512314 | AC22: 14.31687 | AD22: 3.8042868 | AE22: 1.6756757 | AF22: 7.1132376 | AG22: 4.4867977 | AH22: 11.6616 | AI22: 7.0021696 | AJ22: 8.9969387 | AK22: 1.8233333 | AL22: 9.6793466 | AM22: 14.852815 | AN22: 19.263254 | AO22: 26.436782 | AP22: 31.11159 | AQ22: 12.500411 | AR22: 3.3854243 | AS22: 24.432024 | AT22: 9.2961877 | AU22: -1.3656801 | AV22: 10.647465 | AW22: 8.1764294 | AX22: 13.25207 | AY22: 2.74542 | AZ22: 8.4120629 | BA22: 24.406951 | BB22: 10.555436 | BC22: 6.4932659 | BD22: 9.5921661 | BE22: 18.161045 | BF22: 7.9379581 | BG22: 4.4053523 | BH22: 5.5446889 | BI22: 5.5576896 | BJ22: 16.052535 | BK22: -2.8146981 | BL22: -0.68677217 | BM22: 7.3211064 | BN22: 8.4045385 | BO22: 18.800879 | BP22: 26.941484 | BQ22: 20.212493 | BR22: 34.133999
A23: Belgium | B23: BEL | C23: Inflation, consumer prices (annual %) | D23: FP.CPI.TOTL.ZG | E23: 0.29945874 | F23: 0.99268334 | G23: 1.4045951 | H23: 2.1480222 | I23: 4.1687487 | J23: 4.0652093 | K23: 4.1743462 | L23: 2.7302884 | M23: 2.7014581 | N23: 3.753991 | O23: 3.9084882 | P23: 4.343614 | Q23: 5.4484353 | R23: 6.9552732 | S23: 12.677894 | T23: 12.768202 | U23: 9.0686075 | V23: 7.0959964 | W23: 4.4705887 | X23: 4.4690947 | Y23: 6.6486854 | Z23: 7.6274806 | AA23: 8.7265549 | AB23: 7.6616091 | AC23: 6.3417756 | AD23: 4.8687296 | AE23: 1.2943745 | AF23: 1.5533732 | AG23: 1.160939 | AH23: 3.1070553 | AI23: 3.4483067 | AJ23: 3.2153153 | AK23: 2.4279524 | AL23: 2.754427 | AM23: 2.3775478 | AN23: 1.4679587 | AO23: 2.0770234 | AP23: 1.6281618 | AQ23: 0.9492517 | AR23: 1.1208493 | AS23: 2.5445122 | AT23: 2.4692613 | AU23: 1.6452138 | AV23: 1.5889629 | AW23: 2.097285 | AX23: 2.7814321 | AY23: 1.7913158 | AZ23: 1.8230025 | BA23: 4.4862743 | BB23: -0.052074293 | BC23: 2.1895003 | BD23: 3.5325394 | BE23: 2.8386507 | BF23: 1.1127833 | BG23: 0.34955573 | BH23: 0.56183563 | BI23: 1.974434 | BJ23: 2.1246754 | BK23: 2.0525751 | BL23: 1.4382892 | BM23: 0.73693266 | BN23: 2.4425879 | BO23: 9.5976538 | BP23: 4.0486795 | BQ23: 3.1442663 | BR23: 2.4660576
A24: Benin | B24: BEN | C24: Inflation, consumer prices (annual %) | D24: FP.CPI.TOTL.ZG | AL24: 0.44059921 | AM24: 38.530866 | AN24: 14.462548 | AO24: 4.9142397 | AP24: 3.4662959 | AQ24: 5.7533146 | AR24: 0.32672289 | AS24: 4.1654044 | AT24: 3.9842955 | AU24: 2.4891624 | AV24: 1.4872425 | AW24: 0.87389083 | AX24: 5.3645209 | AY24: 3.782177 | AZ24: 1.2980681 | BA24: 7.9472988 | BB24: 0.89607236 | BC24: 2.2078353 | BD24: 2.7042391 | BE24: 6.7446825 | BF24: 0.42888889 | BG24: -0.54875755 | BH24: 0.21878592 | BI24: -0.79331015 | BJ24: 0.043264856 | BK24: 0.91917072 | BL24: 0.73284937 | BM24: 3.0227212 | BN24: 1.7335396 | BO24: 1.3507786 | BP24: 2.7387008 | BQ24: 1.1609309 | BR24: 1.1015525
A25: Burkina Faso | B25: BFA | C25: Inflation, consumer prices (annual %) | D25: FP.CPI.TOTL.ZG | E25: 7.788162 | F25: 18.562139 | G25: 1.6759096 | H25: 5.5742028 | I25: 1.8451232 | J25: -0.73025252 | K25: 2.364106 | L25: -4.3337539 | M25: -0.28671369 | N25: 9.6555294 | O25: 1.7726033 | P25: 2.0612182 | Q25: -2.9233566 | R25: 7.6038904 | S25: 8.7196095 | T25: 18.756947 | U25: -8.4007188 | V25: 29.986104 | W25: 8.2691401 | X25: 14.993466 | Y25: 12.202636 | Z25: 7.5557056 | AA25: 12.059765 | AB25: 8.1537628 | AC25: 4.8469577 | AD25: 6.9060578 | AE25: -2.6117429 | AF25: -2.6817842 | AG25: 4.255616 | AH25: -0.48179872 | AI25: -0.50430339 | AJ25: 2.1626005 | AK25: -1.9911358 | AL25: 0.55345572 | AM25: 25.177876 | AN25: 7.458845 | AO25: 6.0978044 | AP25: 2.3186906 | AQ25: 5.0843334 | AR25: -1.0726136 | AS25: -0.30421217 | AT25: 5.0074329 | AU25: 2.1756948 | AV25: 2.0345657 | AW25: -0.4002287 | AX25: 6.4150402 | AY25: 2.3331086 | AZ25: -0.23062731 | BA25: 10.659798 | BB25: 2.6081767 | BC25: -0.76423073 | BD25: 2.7597672 | BE25: 3.8181524 | BF25: 0.53373851 | BG25: -0.25808952 | BH25: 0.72483898 | BI25: 0.44104145 | BJ25: 1.482999 | BK25: 1.955943 | BL25: -3.2333893 | BM25: 1.8847007 | BN25: 3.6532676 | BO25: 14.290235 | BP25: 0.74291043 | BQ25: 4.1908172 | BR25: -0.58623532
A26: Bangladesh | B26: BGD | C26: Inflation, consumer prices (annual %) | D26: FP.CPI.TOTL.ZG | AF26: 9.8746961 | AG26: 7.412766 | AH26: 6.0454798 | AI26: 6.1267185 | AJ26: 6.3573641 | AK26: 3.6340769 | AL26: 3.0148186 | AM26: 5.3137401 | AN26: 10.297812 | AO26: 2.377129 | AP26: 5.3056011 | AQ26: 8.402238 | AR26: 6.1066959 | AS26: 2.2082562 | AT26: 2.0071737 | AU26: 3.3325649 | AV26: 5.6687077 | AW26: 7.5875364 | AX26: 7.0466182 | AY26: 6.7652612 | AZ26: 9.106985 | BA26: 8.9019449 | BB26: 5.4234724 | BC26: 8.1266764 | BD26: 11.395165 | BE26: 6.2175042 | BF26: 7.5304064 | BG26: 6.9916389 | BH26: 6.1942802 | BI26: 5.5135257 | BJ26: 5.7020702 | BK26: 5.5436214 | BL26: 5.5919964 | BM26: 5.6910747 | BN26: 5.5456543 | BO26: 7.6969544 | BP26: 9.883503 | BQ26: 10.465748 | BR26: 8.7687628
A27: Bulgaria | B27: BGR | C27: Inflation, consumer prices (annual %) | D27: FP.CPI.TOTL.ZG | AE27: 2.7 | AF27: 2.7263875 | AG27: 2.3696682 | AH27: 6.3888889 | AI27: 23.8 | AJ27: 338.44911 | AK27: 91.297933 | AL27: 72.878791 | AM27: 96.057338 | AN27: 62.054834 | AO27: 121.60754 | AP27: 1058.3736 | AQ27: 18.672204 | AR27: 2.5730428 | AS27: 10.316262 | AT27: 7.3609393 | AU27: 5.8101437 | AV27: 2.3486417 | AW27: 6.1471307 | AX27: 5.0388381 | AY27: 7.2615946 | AZ27: 8.4025342 | BA27: 12.34872 | BB27: 2.7532022 | BC27: 2.4389906 | BD27: 4.2199035 | BE27: 2.9545683 | BF27: 0.89009354 | BG27: -1.4181838 | BH27: -0.10463326 | BI27: -0.79864989 | BJ27: 2.0615962 | BK27: 2.8145447 | BL27: 3.1037294 | BM27: 1.672441 | BN27: 3.2977444 | BO27: 15.325259 | BP27: 9.4428414 | BQ27: 2.4465194 | BR27: 4.5808436
A28: Bahrain | B28: BHR | C28: Inflation, consumer prices (annual %) | D28: FP.CPI.TOTL.ZG | K28: 2.1344717 | L28: 4.2580982 | M28: 3.257329 | N28: -0.19412764 | O28: 1.6289813 | P28: 5.7894737 | Q28: 5.0881954 | R28: 14.331827 | S28: 24.392998 | T28: 16.159782 | U28: 22.495767 | V28: 17.731121 | W28: 15.785538 | X28: 2.205992 | Y28: 3.8695251 | Z28: 11.344597 | AA28: 8.8857131 | AB28: 2.9723992 | AC28: 0.32239925 | AD28: -2.6359693 | AE28: -2.2960932 | AF28: -1.7450018 | AG28: 0.30343597 | AH28: 1.4858973 | AI28: 0.92933544 | AJ28: 0.76441974 | AK28: -0.17241379 | AL28: 2.5388601 | AM28: 0.8169109 | AN28: 2.7040348 | AO28: -0.45222738 | AP28: 2.4315513 | AQ28: -0.36653386 | AR28: -1.287588 | AS28: -0.70485295 | AT28: -1.2075718 | AU28: -0.49554014 | AV28: 1.5936255 | AW28: 2.3529412 | AX28: 2.5862069 | AY28: 2.0074697 | AZ28: 3.2566667 | BA28: 3.5260032 | BB28: 2.7955128 | BC28: 1.9618847 | BD28: -0.4000407 | BE28: 2.7573967 | BF28: 3.3000116 | BG28: 2.6475532 | BH28: 1.8486274 | BI28: 2.7867935 | BJ28: 1.3867183 | BK28: 2.0876694 | BL28: 1.00582 | BM28: -2.3177063 | BN28: -0.60631939 | BO28: 3.625741 | BP28: 0.074620678 | BQ28: 0.91963546 | BR28: -0.13770886
A29: Bahamas, The | B29: BHS | C29: Inflation, consumer prices (annual %) | D29: FP.CPI.TOTL.ZG | L29: 5.4377565 | M29: 4.5410315 | N29: 8.9357741 | O29: 6.1520934 | P29: 4.6149718 | Q29: 6.8308113 | R29: 5.4817542 | S29: 13.071846 | T29: 10.359635 | U29: 4.2558366 | V29: 3.1898764 | W29: 6.1090704 | X29: 9.0913933 | Y29: 12.097837 | Z29: 11.114498 | AA29: 6.012621 | AB29: 4 | AC29: 3.9663462 | AD29: 4.6050096 | AE29: 5.4337815 | AF29: 5.756464 | AG29: 4.4024118 | AH29: 5.3876582 | AI29: 4.6693191 | AJ29: 7.1146812 | AK29: 5.7381989 | AL29: 2.7228977 | AM29: 1.3993342 | AN29: 2.066995 | AO29: 1.3791374 | AP29: 0.54415038 | AQ29: 1.3366134 | AR29: 1.2542483 | AS29: 1.6063294 | AT29: 2.0449898 | AU29: 2.1735779 | AV29: 3.0250453 | AW29: 0.98191404 | AX29: 1.5916062 | AY29: 2.3898263 | AZ29: 2.4925779 | BA29: 4.48956 | BB29: 2.0627347 | BC29: 1.3440274 | BD29: 3.1987814 | BE29: 1.9733676 | BF29: 0.72241478 | BG29: 1.5137564 | BH29: 1.861483 | BI29: -0.34637693 | BJ29: 1.518207 | BK29: 2.2658635 | BL29: 2.4912353 | BM29: 0.038521098 | BN29: 2.9049126 | BO29: 5.6054063 | BP29: 3.0529158 | BQ29: 0.40916249 | BR29: 1.1087978
A30: Bosnia and Herzegovina | B30: BIH | C30: Inflation, consumer prices (annual %) | D30: FP.CPI.TOTL.ZG | AY30: 6.1255662 | AZ30: 1.5007771 | BA30: 7.4270431 | BB30: -0.38146428 | BC30: 1.9962124 | BD30: 3.67125 | BE30: 2.0526745 | BF30: -0.093045684 | BG30: -0.89719405 | BH30: -1.036023 | BI30: -1.5841 | BJ30: 0.81013332 | BK30: 1.4171081 | BL30: 0.56278215 | BM30: -1.051296 | BN30: 1.981639 | BO30: 14.020844 | BP30: 6.1059011 | BQ30: 1.6921273 | BR30: 3.9782127
A31: Belarus | B31: BLR | C31: Inflation, consumer prices (annual %) | D31: FP.CPI.TOTL.ZG | AL31: 1190.2292 | AM31: 2221.0166 | AN31: 709.34603 | AO31: 52.712077 | AP31: 63.937366 | AQ31: 72.869717 | AR31: 293.67875 | AS31: 168.62024 | AT31: 61.134933 | AU31: 42.537548 | AV31: 28.39784 | AW31: 18.108242 | AX31: 10.338879 | AY31: 6.997129 | AZ31: 8.4267527 | BA31: 14.837876 | BB31: 12.945656 | BC31: 7.735748 | BD31: 53.228698 | BE31: 59.219736 | BF31: 18.312261 | BG31: 18.119554 | BH31: 13.53449 | BI31: 11.836581 | BJ31: 6.0318373 | BK31: 4.8723022 | BL31: 5.598156 | BM31: 5.5481436 | BN31: 9.4602839 | BO31: 15.209675 | BP31: 5.000599 | BQ31: 5.7853191 | BR31: 6.5987795
A32: Belize | B32: BLZ | C32: Inflation, consumer prices (annual %) | D32: FP.CPI.TOTL.ZG | Z32: 11.22449 | AA32: 6.8390325 | AB32: 4.9960968 | AC32: 3.3828996 | AD32: 6.2371661 | AE32: 0.79977149 | AF32: 2.0119014 | AG32: 3.1388889 | AH32: 2.1276596 | AI32: 3.0590717 | AJ32: 0.7619515 | AK32: 2.3967007 | AL32: 1.4725969 | AM32: 2.569343 | AN32: 2.8896158 | AO32: 5.965021 | AP32: 1.1490376 | AQ32: 2.1952625 | AR32: 2.6213952 | AS32: 3.0674397 | AT32: 3.6514179 | AU32: 4.2402666 | AV32: 2.3180827 | AW32: 6.394431 | AX32: -1.1043104 | AY32: -7.1137677 | AZ32: 2.3180827 | BA32: 6.394431 | BB32: -1.1043104 | BC32: 0.91797738 | BD32: 1.6020562 | BE32: 1.3005807 | BF32: 0.50974777 | BG32: 1.2013996 | BH32: -0.86158401 | BI32: 0.66342717 | BJ32: 1.1476534 | BK32: 0.26998262 | BL32: 0.18706939 | BM32: 0.12143464 | BN32: 3.2356366 | BO32: 6.2768932 | BP32: 4.3898402 | BQ32: 3.2895599 | BR32: 1.0628155
A33: Bermuda | B33: BMU | C33: Inflation, consumer prices (annual %) | D33: FP.CPI.TOTL.ZG
A34: Bolivia | B34: BOL | C34: Inflation, consumer prices (annual %) | D34: FP.CPI.TOTL.ZG | E34: 11.533153 | F34: 7.5614931 | G34: 5.8793314 | H34: -0.70635721 | I34: 10.181818 | J34: 2.860286 | K34: 6.9518717 | L34: 11.2 | M34: 5.4706235 | N34: 2.2097485 | O34: 3.9555092 | P34: 3.6746143 | Q34: 6.511544 | R34: 31.486029 | S34: 62.836076 | T34: 7.976746 | U34: 4.4940116 | V34: 8.1072555 | W34: 10.355672 | X34: 19.719717 | Y34: 47.24165 | Z34: 32.133601 | AA34: 123.53572 | AB34: 275.58628 | AC34: 1281.3499 | AD34: 11749.64 | AE34: 276.33597 | AF34: 14.578698 | AG34: 16.002091 | AH34: 15.173468 | AI34: 17.118775 | AJ34: 21.44707 | AK34: 12.060324 | AL34: 8.527877 | AM34: 7.8740442 | AN34: 10.193207 | AO34: 12.425487 | AP34: 4.7084444 | AQ34: 7.673229 | AR34: 2.1595163 | AS34: 4.60823 | AT34: 1.5896538 | AU34: 0.92825885 | AV34: 3.337275 | AW34: 4.4373808 | AX34: 5.3932311 | AY34: 4.282396 | AZ34: 8.7056092 | BA34: 14.006811 | BB34: 3.3464542 | BC34: 2.5032761 | BD34: 9.8844642 | BE34: 4.5156029 | BF34: 5.7364002 | BG34: 5.7666007 | BH34: 4.0596104 | BI34: 3.6232143 | BJ34: 2.8227581 | BK34: 2.2720599 | BL34: 1.839545 | BM34: 0.94074215 | BN34: 0.73738372 | BO34: 1.7463287 | BP34: 2.576888 | BQ34: 5.0997657 | BR34: 19.517121
A35: Brazil | B35: BRA | C35: Inflation, consumer prices (annual %) | D35: FP.CPI.TOTL.ZG | Z35: 101.72507 | AA35: 100.54336 | AB35: 135.02768 | AC35: 192.12173 | AD35: 225.98967 | AE35: 147.14283 | AF35: 228.33616 | AG35: 629.11451 | AH35: 1430.7237 | AI35: 2947.7328 | AJ35: 432.78666 | AK35: 951.96205 | AL35: 1927.3808 | AM35: 2075.8884 | AN35: 66.007034 | AO35: 15.757666 | AP35: 6.9267125 | AQ35: 3.1950763 | AR35: 4.8584475 | AS35: 7.0441411 | AT35: 6.840359 | AU35: 8.4501644 | AV35: 14.71492 | AW35: 6.5971851 | AX35: 6.8695372 | AY35: 4.1835681 | AZ35: 3.641273 | BA35: 5.6785939 | BB35: 4.8880348 | BC35: 5.0387269 | BD35: 6.6364496 | BE35: 5.4034991 | BF35: 6.2043107 | BG35: 6.3290402 | BH35: 9.029901 | BI35: 8.7391435 | BJ35: 3.4463734 | BK35: 3.6648503 | BL35: 3.7329762 | BM35: 3.211768 | BN35: 8.3016598 | BO35: 9.2801061 | BP35: 4.5935628 | BQ35: 4.3674641 | BR35: 5.0167528
A36: Barbados | B36: BRB | C36: Inflation, consumer prices (annual %) | D36: FP.CPI.TOTL.ZG | L36: 3.6348752 | M36: 7.4887432 | N36: 5.8352319 | O36: 7.2842164 | P36: 7.4692557 | Q36: 11.876656 | R36: 16.855082 | S36: 38.922928 | T36: 20.294469 | U36: 4.9867681 | V36: 8.3523697 | W36: 9.4823826 | X36: 13.169836 | Y36: 14.43052 | Z36: 14.567563 | AA36: 10.332466 | AB36: 5.2302988 | AC36: 4.6857973 | AD36: 3.9151053 | AE36: 1.3300685 | AF36: 3.3117311 | AG36: 4.8588592 | AH36: 6.1901141 | AI36: 3.0745727 | AJ36: 6.2575266 | AK36: 6.093893 | AL36: 1.1134393 | AM36: 0.077204388 | AN36: 1.8788628 | AO36: 2.3861522 | AP36: 7.7105388 | AQ36: -1.2688866 | AR36: 1.5600624 | AS36: 2.435813 | AT36: 2.5778349 | AU36: 0.12524946 | AV36: 1.6194332 | AW36: 1.3944223 | AX36: 6.0821873 | AY36: 7.3076626 | AZ36: 4.0342298 | BA36: 8.1081081 | BB36: 3.6438619 | BC36: 5.8242185 | BD36: 9.4322024 | BE36: 4.5333475 | BF36: 1.8141044 | BG36: 1.7695032 | BH36: -1.1127899 | BI36: 1.2819281 | BJ36: 4.6601846 | BK36: 3.1060057 | BL36: 1.6766247 | BP36: 3.1871891 | BQ36: 1.4464366 | BR36: 0.84657656
A37: Brunei Darussalam | B37: BRN | C37: Inflation, consumer prices (annual %) | D37: FP.CPI.TOTL.ZG | Z37: 9.1370558 | AA37: 6.3565891 | AB37: 1.1661808 | AC37: 3.0739673 | AD37: 2.3532153 | AE37: 1.7812429 | AF37: 1.2468549 | AG37: 1.1928429 | AH37: 1.3043004 | AI37: 2.1386629 | AJ37: 1.6 | AK37: 1.2795276 | AL37: 4.2517007 | AM37: 2.4625184 | AN37: 5.9666414 | AO37: 1.9961365 | AP37: 1.71156 | AQ37: -0.44137931 | AR37: -0.4156276 | AS37: 1.5581525 | AT37: 0.59589041 | AU37: -2.3149724 | AV37: 0.3 | AW37: 0.81422399 | AX37: 1.2444371 | AY37: 0.15988808 | AZ37: 0.96777412 | BA37: 2.0849802 | BB37: 1.0357177 | BC37: 0.35686913 | BD37: 0.13791156 | BE37: 0.11176626 | BF37: 0.38920505 | BG37: -0.20710873 | BH37: -0.41512193 | BI37: -0.73906872 | BJ37: -0.17131153 | BK37: 0.15052349 | BL37: -0.37137214 | BM37: 1.9403062 | BN37: 1.7334139 | BO37: 3.6822503 | BP37: 0.35706431 | BQ37: -0.38867417 | BR37: -0.30299441
A38: Bhutan | B38: BTN | C38: Inflation, consumer prices (annual %) | D38: FP.CPI.TOTL.ZG | Z38: 9.9723757 | AA38: 9.8467722 | AB38: 18.057779 | AC38: 7.0377066 | AD38: 1.8820123 | AE38: 9.964476 | AF38: 6.3317719 | AG38: 10.096714 | AH38: 8.7798372 | AI38: 10.011838 | AJ38: 12.275173 | AK38: 15.975217 | AL38: 11.198017 | AM38: 7.0099536 | AN38: 9.4875484 | AO38: 8.7900138 | AP38: 6.5054872 | AQ38: 10.58559 | AR38: 6.7769939 | AS38: 4.0121208 | AT38: 3.4147895 | AU38: 2.4553571 | AV38: 2.5723086 | AW38: 4.105937 | AX38: 5.312631 | AY38: 5.0004544 | AZ38: 5.1561114 | BA38: 8.3271605 | BB38: 4.3611222 | BC38: 7.0363832 | BD38: 8.8489857 | BE38: 10.919657 | BF38: 8.7763835 | BG38: 8.2710609 | BH38: 4.548144 | BI38: 3.2198869 | BJ38: 4.9550837 | BK38: 2.7239639 | BL38: 2.7264304 | BM38: 5.6293652 | BN38: 7.3468144 | BO38: 5.6391667 | BP38: 4.2293442 | BQ38: 2.7613157 | BR38: 3.5551366
A39: Botswana | B39: BWA | C39: Inflation, consumer prices (annual %) | D39: FP.CPI.TOTL.ZG | T39: 11.974755 | U39: 11.732424 | V39: 13.168724 | W39: 9.0439883 | X39: 11.736231 | Y39: 13.632425 | Z39: 16.428027 | AA39: 11.137206 | AB39: 10.477144 | AC39: 8.577469 | AD39: 8.0945758 | AE39: 10.001716 | AF39: 9.8019339 | AG39: 8.3516796 | AH39: 11.575015 | AI39: 11.396346 | AJ39: 11.765016 | AK39: 16.167612 | AL39: 14.330803 | AM39: 10.542921 | AN39: 10.512546 | AO39: 10.082858 | AP39: 8.7199313 | AQ39: 6.6613987 | AR39: 7.7492962 | AS39: 8.6014851 | AT39: 6.5590377 | AU39: 8.0327966 | AV39: 9.1899027 | AW39: 6.9457036 | AX39: 8.6102253 | AY39: 11.555219 | AZ39: 7.0809985 | BA39: 12.702188 | BB39: 8.027297 | BC39: 6.9488766 | BD39: 8.4598723 | BE39: 7.5369026 | BF39: 5.8846071 | BG39: 4.4022531 | BH39: 3.0620317 | BI39: 2.8149579 | BJ39: 3.3082808 | BK39: 3.2380156 | BL39: 2.7728644 | BM39: 1.8903592 | BN39: 7.2409777 | BO39: 11.665567 | BP39: 5.0676155 | BQ39: 2.8183513 | BR39: 2.6598504
A40: Central African Republic | B40: CAF | C40: Inflation, consumer prices (annual %) | D40: FP.CPI.TOTL.ZG | Z40: -0.033333333 | AA40: 13.296099 | AB40: 14.612611 | AC40: 2.5422097 | AD40: 10.42384 | AE40: 2.2451525 | AF40: -6.9868027 | AG40: -3.9644688 | AH40: 0.68905581 | AI40: -0.012330456 | AJ40: -2.7623628 | AK40: -1.0336081 | AL40: -2.9153585 | AM40: 24.571014 | AN40: 19.189404 | AO40: 3.7249411 | AP40: 1.6113135 | AQ40: -1.885201 | AR40: -1.4142022 | AS40: 3.2034009 | AT40: 3.8348606 | AU40: 2.331817 | AV40: 4.1347091 | AW40: -2.066406 | AX40: 2.8835207 | AY40: 6.6952647 | AZ40: 0.95991762 | BA40: 9.258951 | BB40: 3.5212623 | BC40: 1.4910237 | BD40: 1.1944757 | BE40: 5.4782959 | BF40: 6.9887934 | BG40: 14.898684 | BH40: 1.4029702 | BI40: 4.9454328 | BJ40: 4.1807233 | BK40: 1.6121569 | BL40: 2.6853736 | BM40: 1.7101566 | BN40: 4.2593642 | BO40: 5.5831674 | BP40: 2.9791385 | BQ40: 1.477336 | BR40: 1.0019801
A41: Canada | B41: CAN | C41: Inflation, consumer prices (annual %) | D41: FP.CPI.TOTL.ZG | E41: 1.3586957 | F41: 1.0187668 | G41: 1.0615711 | H41: 1.6281513 | I41: 1.9121447 | J41: 2.3326572 | K41: 3.8156591 | L41: 3.5799523 | M41: 4.0552995 | N41: 4.5615589 | O41: 3.3460398 | P41: 2.704918 | Q41: 4.9880287 | R41: 7.4876473 | S41: 10.997171 | T41: 10.672189 | U41: 7.5417386 | V41: 7.9764454 | W41: 8.9737234 | X41: 9.144677 | Y41: 10.129221 | Z41: 12.471612 | AA41: 10.768972 | AB41: 5.863588 | AC41: 4.3047783 | AD41: 3.9620305 | AE41: 4.1947863 | AF41: 4.3561087 | AG41: 4.0282341 | AH41: 4.9836219 | AI41: 4.7804769 | AJ41: 5.6258641 | AK41: 1.4901329 | AL41: 1.8650794 | AM41: 0.16556291 | AN41: 2.1487603 | AO41: 1.5705311 | AP41: 1.6212164 | AQ41: 0.99594246 | AR41: 1.734843 | AS41: 2.71944 | AT41: 2.5251201 | AU41: 2.2583944 | AV41: 2.7585632 | AW41: 1.8572587 | AX41: 2.213552 | AY41: 2.0020254 | AZ41: 2.138384 | BA41: 2.3702707 | BB41: 0.2994668 | BC41: 1.7768715 | BD41: 2.9121351 | BE41: 1.5156782 | BF41: 0.9382919 | BG41: 1.9066359 | BH41: 1.1252414 | BI41: 1.4287595 | BJ41: 1.5968841 | BK41: 2.2682257 | BL41: 1.949269 | BM41: 0.71699963 | BN41: 3.3951932 | BO41: 6.8028012 | BP41: 3.8790016 | BQ41: 2.3815838 | BR41: 2.0723241
A42: Central Europe and the Baltics | B42: CEB | C42: Inflation, consumer prices (annual %) | D42: FP.CPI.TOTL.ZG | AJ42: 118.52757 | AK42: 150.61586 | AL42: 72.878791 | AM42: 35.924705 | AN42: 27.951389 | AO42: 19.794967 | AP42: 8.8811294 | AQ42: 8.2083333 | AR42: 4.0191388 | AS42: 8.9065536 | AT42: 5.753643 | AU42: 3.1271422 | AV42: 2.3486417 | AW42: 3.5953918 | AX42: 3.3171782 | AY42: 3.9210432 | AZ42: 4.8373293 | BA42: 6.3586638 | BB42: 2.7532022 | BC42: 1.7968631 | BD42: 4.130288 | BE42: 3.3349227 | BF42: 1.4382979 | BG42: 0.053821313 | BH42: -0.464499 | BI42: -0.051046452 | BJ42: 2.0759355 | BK42: 2.5344542 | BL42: 2.6645613 | BM42: 1.672441 | BN42: 3.8398449 | BO42: 14.608144 | BP42: 9.4428414 | BQ42: 2.7576091 | BR42: 3.8141953
...

Sheet Raw_GDP_Growth
A1: Data Source | B1: World Development Indicators
A3: Last Updated Date | B3: 2026-10-08
A5: Country Name | B5: Country Code | C5: Indicator Name | D5: Indicator Code | E5: 1960 | F5: 1961 | G5: 1962 | H5: 1963 | I5: 1964 | J5: 1965 | K5: 1966 | L5: 1967 | M5: 1968 | N5: 1969 | O5: 1970 | P5: 1971 | Q5: 1972 | R5: 1973 | S5: 1974 | T5: 1975 | U5: 1976 | V5: 1977 | W5: 1978 | X5: 1979 | Y5: 1980 | Z5: 1981 | AA5: 1982 | AB5: 1983 | AC5: 1984 | AD5: 1985 | AE5: 1986 | AF5: 1987 | AG5: 1988 | AH5: 1989 | AI5: 1990 | AJ5: 1991 | AK5: 1992 | AL5: 1993 | AM5: 1994 | AN5: 1995 | AO5: 1996 | AP5: 1997 | AQ5: 1998 | AR5: 1999 | AS5: 2000 | AT5: 2001 | AU5: 2002 | AV5: 2003 | AW5: 2004 | AX5: 2005 | AY5: 2006 | AZ5: 2007 | BA5: 2008 | BB5: 2009 | BC5: 2010 | BD5: 2011 | BE5: 2012 | BF5: 2013 | BG5: 2014 | BH5: 2015 | BI5: 2016 | BJ5: 2017 | BK5: 2018 | BL5: 2019 | BM5: 2020 | BN5: 2021 | BO5: 2022 | BP5: 2023 | BQ5: 2024 | BR5: 2025
A6: Aruba | B6: ABW | C6: GDP growth (annual %) | D6: NY.GDP.MKTP.KD.ZG | AF6: 16.078431 | AG6: 18.648649 | AH6: 12.129841 | AI6: 3.9614017 | AJ6: 7.9628717 | AK6: 5.882354 | AL6: 7.3076932 | AM6: 8.2039013 | AN6: 2.5471437 | AO6: 1.1857885 | AP6: 7.046875 | AQ6: 1.9919844 | AR6: 1.2380418 | AS6: 7.6229206 | AT6: 4.1820016 | AU6: -0.94495348 | AV6: 1.1105046 | AW6: 7.2937281 | AX6: -0.38313767 | AY6: 1.1274115 | AZ6: 3.0895444 | BA6: 1.8357552 | BB6: -11.677741 | BC6: -2.7334568 | BD6: 3.3692372 | BE6: -1.0407999 | BF6: 6.4314608 | BG6: 1.4260995 | BH6: 3.6114791 | BI6: 1.2343354 | BJ6: 3.4934299 | BK6: 3.2124711 | BL6: 1.2291441 | BM6: -23.940059 | BN6: 14.833692 | BO6: 10.607961 | BP6: 9.5163602 | BQ6: 6.8107767
A7: Africa Eastern and Southern | B7: AFE | C7: GDP growth (annual %) | D7: NY.GDP.MKTP.KD.ZG | F7: 0.41860452 | G7: 7.9370895 | H7: 5.6243171 | I7: 4.6503492 | J7: 5.1381532 | K7: 4.8275677 | L7: 5.3388033 | M7: 4.1564974 | N7: 5.1213578 | O7: 1.1123414 | P7: 5.4824776 | Q7: 2.7637494 | R7: 4.6210541 | S7: 5.47247 | T7: 1.3746952 | U7: 2.3486777 | V7: 1.1100761 | W7: 1.48045 | X7: 2.9275162 | Y7: 5.4525093 | Z7: 3.9285514 | AA7: 0.30873317 | AB7: 0.063309544 | AC7: 3.405999 | AD7: -0.086267474 | AE7: 2.2708785 | AF7: 3.938606 | AG7: 4.2863074 | AH7: 2.6661202 | AI7: 0.12124811 | AJ7: -0.1060836 | AK7: -2.3959973 | AL7: -0.83899814 | AM7: 1.92196 | AN7: 4.353927 | AO7: 5.4988963 | AP7: 3.8563472 | AQ7: 1.7747373 | AR7: 2.6341227 | AS7: 3.1809474 | AT7: 3.5033467 | AU7: 3.9168475 | AV7: 3.0092685 | AW7: 5.6346823 | AX7: 6.1737294 | AY7: 6.6374604 | AZ7: 6.7023633 | BA7: 4.4393342 | BB7: 0.9189169 | BC7: 5.3352128 | BD7: 3.7912405 | BE7: 1.8801298 | BF7: 4.6340001 | BG7: 3.9163617 | BH7: 2.9339035 | BI7: 2.2925006 | BJ7: 2.6788627 | BK7: 2.7062074 | BL7: 1.9355926 | BM7: -2.9307641 | BN7: 4.452643 | BO7: 3.6680291 | BP7: 1.9413816 | BQ7: 2.7879315 | BR7: 3.7430159
A8: Afghanistan | B8: AFG | C8: GDP growth (annual %) | D8: NY.GDP.MKTP.KD.ZG | AT8: -9.4319741 | AU8: 28.600001 | AV8: 8.8322778 | AW8: 1.414118 | AX8: 11.229715 | AY8: 5.3574032 | AZ8: 13.82632 | BA8: 3.9249838 | BB8: 21.390528 | BC8: 14.362441 | BD8: 0.42635478 | BE8: 12.752287 | BF8: 5.6007447 | BG8: 2.7245434 | BH8: 1.4513147 | BI8: 2.2603142 | BJ8: 2.6470032 | BK8: 1.1892281 | BL8: 3.9116034 | BM8: -2.3511007 | BN8: -20.738839 | BO8: -6.240172 | BP8: 2.2669437 | BQ8: 1.8731928
A9: Africa Western and Central | B9: AFW | C9: GDP growth (annual %) | D9: NY.GDP.MKTP.KD.ZG | F9: 1.8695932 | G9: 3.7260158 | H9: 7.0381715 | I9: 5.36458 | J9: 4.10566 | K9: -1.5129592 | L9: -8.9663244 | M9: 1.5745921 | N9: 15.016524 | O9: 17.309161 | P9: 10.407117 | Q9: 3.1672607 | R9: 3.921881 | S9: 9.9159601 | T9: -2.0139101 | U9: 8.4221251 | V9: 4.5611099 | W9: -1.9152738 | X9: 5.0308337 | Y9: 1.8685404 | Z9: -6.6405572 | AA9: -3.2706126 | AB9: -6.2893278 | AC9: 0.48370524 | AD9: 5.3198983 | AE9: 1.2663631 | AF9: 1.410625 | AG9: 4.7612941 | AH9: 1.7235101 | AI9: 5.6006394 | AJ9: 1.1181368 | AK9: 2.2891577 | AL9: -1.3253624 | AM9: -0.22887373 | AN9: 1.8518584 | AO9: 4.6218579 | AP9: 4.3875653 | AQ9: 3.6155743 | AR9: 1.5180542 | AS9: 3.8119429 | AT9: 5.2485252 | AU9: 9.9430962 | AV9: 5.6263902 | AW9: 8.0713967 | AX9: 5.7974954 | AY9: 5.2874693 | AZ9: 5.4473398 | BA9: 6.2106556 | BB9: 6.1410559 | BC9: 7.000647 | BD9: 4.9220318 | BE9: 5.1296897 | BF9: 6.0466542 | BG9: 5.6915234 | BH9: 2.932911 | BI9: 0.17617172 | BJ9: 2.3027606 | BK9: 2.8999542 | BL9: 3.2831424 | BM9: -3.7187933 | BN9: 2.5454727 | BO9: 4.4771076 | BP9: 3.6445909 | BQ9: 4.5961834 | BR9: 4.6001
A10: Angola | B10: AGO | C10: GDP growth (annual %) | D10: NY.GDP.MKTP.KD.ZG | Z10: -4.4000012 | AA10: 0 | AB10: 4.2000014 | AC10: 6.0000022 | AD10: 3.4999995 | AE10: 2.9000017 | AF10: 4.0827486 | AG10: 6.1288905 | AH10: 0.041621462 | AI10: -3.4500987 | AJ10: 0.9913593 | AK10: -5.8382807 | AL10: -23.983417 | AM10: 1.3393634 | AN10: 15 | AO10: 13.54437 | AP10: 7.2742774 | AQ10: 4.6911465 | AR10: 2.1814897 | AS10: 3.0546242 | AT10: 4.2059986 | AU10: 13.665689 | AV10: 3.4873124 | AW10: 11.419863 | AX10: 14.154778 | AY10: 11.841818 | AZ10: 13.002689 | BA10: 10.786636 | BB10: 1.9955891 | BC10: 5.2936657 | BD10: 3.5938696 | BE10: 8.5031228 | BF10: 4.8830613 | BG10: 4.6557236 | BH10: 0.76317771 | BI10: -0.23307695 | BJ10: -0.16468866 | BK10: -0.50669754 | BL10: -1.0552341 | BM10: -5.2734913 | BN10: 1.0905837 | BO10: 3.5574921 | BP10: 1.3201659 | BQ10: 4.9526786 | BR10: 3.1335354
A11: Albania | B11: ALB | C11: GDP growth (annual %) | D11: NY.GDP.MKTP.KD.ZG | Z11: 5.7456353 | AA11: 2.9485968 | AB11: 1.1049383 | AC11: -1.2515966 | AD11: 1.780644 | AE11: 5.6372432 | AF11: -0.78784265 | AG11: -1.4200397 | AH11: 9.836549 | AI11: -9.5756402 | AJ11: -28.002142 | AK11: -7.1871109 | AL11: 9.5594117 | AM11: 8.3028666 | AN11: 13.322333 | AO11: 7.3363289 | AP11: -11.711573 | AQ11: 8.3100252 | AR11: 12.250728 | AS11: 7.4628587 | AT11: 8.8637307 | AU11: 4.6283959 | AV11: 5.3332643 | AW11: 5.2662617 | AX11: 5.1308219 | AY11: 6.0189812 | AZ11: 6.5000926 | BA11: 6.9070623 | BB11: 2.6907515 | BC11: 2.9731544 | BD11: 2.4635168 | BE11: 0.98412988 | BF11: 1.7072283 | BG11: 2.240227 | BH11: 2.2277041 | BI11: 3.9089355 | BJ11: 3.2831759 | BK11: 3.6714193 | BL11: 2.0625779 | BM11: -3.3137564 | BN11: 8.9695762 | BO11: 4.8268006 | BP11: 4.0154172 | BQ11: 4.0459285 | BR11: 3.7889384
A12: Andorra | B12: AND | C12: GDP growth (annual %) | D12: NY.GDP.MKTP.KD.ZG | P12: 4.6494654 | Q12: 8.1497435 | R12: 7.7884672 | S12: 5.6187896 | T12: 0.54220567 | U12: 3.3037871 | V12: 2.8385756 | W12: 1.4630002 | X12: 0.041557223 | Y12: 2.2087276 | Z12: -0.13247449 | AA12: 1.2464611 | AB12: 1.7701183 | AC12: 1.7846867 | AD12: 2.321433 | AE12: 3.2533218 | AF12: 5.5471222 | AG12: 5.0943262 | AH12: 4.8270343 | AI12: 3.7813875 | AJ12: 2.5460035 | AK12: 0.92921404 | AL12: -1.0314844 | AM12: 2.3831822 | AN12: 2.7575016 | AO12: 4.6497387 | AP12: 9.0676721 | AQ12: 3.1947934 | AR12: 4.0990789 | AS12: 3.5283624 | AT12: 8.1193577 | AU12: 4.5463622 | AV12: 8.6942037 | AW12: 8.1356763 | AX12: 5.397796 | AY12: 4.8086887 | AZ12: 1.5531881 | BA12: -5.5591864 | BB12: -5.3028465 | BC12: -1.974958 | BD12: -0.0080697534 | BE12: -4.9744437 | BF12: -3.5475965 | BG12: 2.5044655 | BH12: 1.4341404 | BI12: 3.7096781 | BJ12: 0.34607189 | BK12: 1.5887655 | BL12: 2.0155476 | BM12: -11.18394 | BN12: 8.2867788 | BO12: 9.5646123 | BP12: 2.5835548 | BQ12: 3.8491605 | BR12: 3.8680345
A13: Arab World | B13: ARB | C13: GDP growth (annual %) | D13: NY.GDP.MKTP.KD.ZG | L13: 6.786332 | M13: 10.780642 | N13: 7.4546574 | O13: 22.941207 | P13: 7.4845697 | Q13: 13.939193 | R13: 13.291504 | S13: 10.513404 | T13: -0.038970754 | U13: 14.310714 | V13: 6.5891794 | W13: 2.954258 | X13: 10.647739 | Y13: 6.2791327 | Z13: 0.86580421 | AA13: -5.9736566 | AB13: -3.7601792 | AC13: 1.2453435 | AD13: -0.84660702 | AE13: -0.77095957 | AF13: 0.25409336 | AG13: 3.2791978 | AH13: 3.7932962 | AI13: 7.8321576 | AJ13: -0.69384519 | AK13: 6.5762999 | AL13: 3.2556746 | AM13: 3.3554661 | AN13: 2.8010926 | AO13: 4.8149922 | AP13: 5.4663114 | AQ13: 4.7704738 | AR13: 2.778466 | AS13: 6.3361914 | AT13: 2.143879 | AU13: 1.2934637 | AV13: 4.1919969 | AW13: 9.0874085 | AX13: 5.5790716 | AY13: 6.3082114 | AZ13: 4.6294113 | BA13: 5.59734 | BB13: 0.68094799 | BC13: 4.7365057 | BD13: 3.8486068 | BE13: 5.4813797 | BF13: 2.5856464 | BG13: 2.5877736 | BH13: 3.3499828 | BI13: 3.5724563 | BJ13: 1.3312699 | BK13: 2.6703834 | BL13: 1.7494924 | BM13: -5.2864142 | BN13: 4.431404 | BO13: 6.9966763 | BP13: 1.6487293 | BQ13: 2.0052181 | BR13: 3.6775799
A14: United Arab Emirates | B14: ARE | C14: GDP growth (annual %) | D14: NY.GDP.MKTP.KD.ZG | P14: 36.612378 | Q14: 39.079638 | R14: 76.620155 | S14: 14.498041 | T14: 6.2276109 | U14: 16.526679 | V14: 21.439699 | W14: -1.5896194 | X14: 20.923487 | Y14: 23.874579 | Z14: 4.6593642 | AA14: -6.7191448 | AB14: -4.7460697 | AC14: 4.017138 | AD14: -3.5948668 | AE14: -14.957772 | AF14: 3.3814507 | AG14: -2.6190537 | AH14: 12.338371 | AI14: 18.327723 | AJ14: 0.86010433 | AK14: 3.3452817 | AL14: 1.2610979 | AM14: 6.8960757 | AN14: 6.6876693 | AO14: 5.7985509 | AP14: 8.1902626 | AQ14: 0.29222649 | AR14: 2.9020534 | AS14: 10.852838 | AT14: 1.3989216 | AU14: 2.4333749 | AV14: 8.8005781 | AW14: 9.5665263 | AX14: 4.8551366 | AY14: 9.8372792 | AZ14: 3.1844128 | BA14: 3.1918124 | BB14: -5.2429219 | BC14: 1.60285 | BD14: 6.7365117 | BE14: 4.6832564 | BF14: 4.9184506 | BG14: 4.6329179 | BH14: 7.0876662 | BI14: 5.6579015 | BJ14: -1.0613711 | BK14: 1.5372063 | BL14: 1.2712912 | BM14: -8.6934336 | BN14: 4.5528014 | BO14: 7.5145241 | BP14: 4.3011365 | BQ14: 3.991812
A15: Argentina | B15: ARG | C15: GDP growth (annual %) | D15: NY.GDP.MKTP.KD.ZG | F15: 5.4278429 | G15: -0.85202152 | H15: -5.3081968 | I15: 10.130298 | J15: 10.569433 | K15: -0.65972617 | L15: 3.1919966 | M15: 4.8225008 | N15: 9.679526 | O15: 3.0456433 | P15: 5.6581311 | Q15: 1.6284165 | R15: 2.811754 | S15: 5.5338044 | T15: -0.028412104 | U15: -2.0182515 | V15: 6.9341478 | W15: -4.5061248 | X15: 10.222763 | Y15: 1.5187839 | Z15: -5.1897891 | AA15: -0.73565916 | AB15: 4.3490933 | AC15: 1.5707387 | AD15: -5.1890244 | AE15: 6.1533771 | AF15: 2.7048688 | AG15: -1.0899333 | AH15: -7.1569497 | AI15: -2.4672138 | AJ15: 9.1331106 | AK15: 7.9372916 | AL15: 8.2069791 | AM15: 5.8362007 | AN15: -2.8452096 | AO15: 5.5266898 | AP15: 8.1110468 | AQ15: 3.8501789 | AR15: -3.385457 | AS15: -0.78899894 | AT15: -4.4088397 | AU15: -10.894485 | AV15: 8.8370408 | AW15: 9.0295733 | AX15: 8.8516599 | AY15: 8.0471515 | AZ15: 9.0076509 | BA15: 4.0572331 | BB15: -5.9185251 | BC15: 10.125398 | BD15: 6.0039517 | BE15: -1.0264205 | BF15: 2.4053238 | BG15: -2.5126153 | BH15: 2.7311598 | BI15: -2.0803278 | BJ15: 2.818503 | BK15: -2.6173965 | BL15: -2.000861 | BM15: -9.9004848 | BN15: 10.441812 | BO15: 6.0207454 | BP15: -1.855788 | BQ15: -1.3429307 | BR15: 4.3673333
A16: Armenia | B16: ARM | C16: GDP growth (annual %) | D16: NY.GDP.MKTP.KD.ZG | AJ16: -11.699998 | AK16: -41.800003 | AL16: -8.7999988 | AM16: 5.4000028 | AN16: 6.8999984 | AO16: 5.8654007 | AP16: 3.3210797 | AQ16: 7.3 | AR16: 3.3 | AS16: 5.9 | AT16: 9.6 | AU16: 13.2 | AV16: 14 | AW16: 10.5 | AX16: 13.9 | AY16: 13.2 | AZ16: 13.7 | BA16: 6.9 | BB16: -14.1 | BC16: 2.2 | BD16: 4.7 | BE16: 7.2 | BF16: 3.3 | BG16: 3.6 | BH16: 3.2 | BI16: 0.2 | BJ16: 7.5 | BK16: 5.2 | BL16: 7.6 | BM16: -7.2 | BN16: 5.8 | BO16: 12.6 | BP16: 8.3 | BQ16: 5.9 | BR16: 7.2
A17: American Samoa | B17: ASM | C17: GDP growth (annual %) | D17: NY.GDP.MKTP.KD.ZG | AV17: 0.96551724 | AW17: 0.40983607 | AX17: -0.40816327 | AY17: -4.0983607 | AZ17: 1.8518519 | BA17: -2.6573427 | BB17: -4.1666667 | BC17: 0.29985007 | BD17: 0 | BE17: -4.3348281 | BF17: -2.5 | BG17: 1.7628205 | BH17: 3.1496063 | BI17: -1.6793893 | BJ17: -6.9875776 | BK17: 2.6711185 | BL17: -0.48780488 | BM17: 4.4117647 | BN17: -0.78247261 | BO17: 1.7350158
A18: Antigua and Barbuda | B18: ATG | C18: GDP growth (annual %) | D18: NY.GDP.MKTP.KD.ZG | W18: 4.3835125 | X18: 8.0794462 | Y18: 8.1619839 | Z18: 3.8144482 | AA18: -0.083506684 | AB18: 5.3638188 | AC18: 10.16523 | AD18: 7.6438444 | AE18: 11.493669 | AF18: 6.6261349 | AG18: 5.213132 | AH18: 5.2523015 | AI18: 3.0118132 | AJ18: 2.1768522 | AK18: 1.1585508 | AL18: 5.2798868 | AM18: 6.6764065 | AN18: -4.3597847 | AO18: 6.6049449 | AP18: 5.4712558 | AQ18: 4.7312791 | AR18: 3.7077459 | AS18: 6.2035521 | AT18: -4.5481098 | AU18: 1.0272349 | AV18: 6.0766367 | AW18: 5.7671034 | AX18: 6.4736894 | AY18: 12.708147 | AZ18: 9.3151827 | BA18: -0.014006598 | BB18: -11.962879 | BC18: -7.8405068 | BD18: -1.9587426 | BE18: 3.3731427 | BF18: -0.60098233 | BG18: 2.1982919 | BH18: 1.42162 | BI18: 4.1203675 | BJ18: 2.7127266 | BK18: 6.7120049 | BL18: 3.1722219 | BM18: -18.868777 | BN18: 8.1728631 | BO18: 8.4977634 | BP18: 3.8655016 | BQ18: 2.5404419 | BR18: 4.99804
A19: Australia | B19: AUS | C19: GDP growth (annual %) | D19: NY.GDP.MKTP.KD.ZG | F19: 2.4808574 | G19: 1.2969318 | H19: 6.2143763 | I19: 6.9775719 | J19: 5.9775054 | K19: 2.3810335 | L19: 6.3068995 | M19: 5.0951298 | N19: 7.0476024 | O19: 7.1746998 | P19: 4.0009866 | Q19: 3.9069786 | R19: 2.6185459 | S19: 4.106611 | T19: 1.3387006 | U19: 2.5878221 | V19: 3.5923758 | W19: 0.89536344 | X19: 4.0515509 | Y19: 3.0345351 | Z19: 3.3424202 | AA19: 3.32865 | AB19: -2.2258235 | AC19: 4.5644787 | AD19: 5.2816981 | AE19: 3.9697631 | AF19: 2.556768 | AG19: 5.7613701 | AH19: 3.8790178 | AI19: 3.5729757 | AJ19: -0.38463136 | AK19: 0.43306586 | AL19: 4.0458337 | AM19: 3.9788443 | AN19: 3.8901719 | AO19: 3.8656748 | AP19: 3.9179581 | AQ19: 4.6768137 | AR19: 5.0282204 | AS19: 3.9160575 | AT19: 2.0314588 | AU19: 3.9498054 | AV19: 3.0912801 | AW19: 4.2189415 | AX19: 3.1554812 | AY19: 2.7709262 | AZ19: 3.7894712 | BA19: 3.623985 | BB19: 1.9548483 | BC19: 2.210048 | BD19: 2.3947349 | BE19: 3.9524714 | BF19: 2.654453 | BG19: 2.6011898 | BH19: 2.1643478 | BI19: 2.7556407 | BJ19: 2.2933103 | BK19: 2.8741704 | BL19: 2.194017 | BM19: -0.1335319 | BN19: 2.0069484 | BO19: 4.2530456 | BP19: 3.583821 | BQ19: 1.3734077 | BR19: 1.3503979
A20: Austria | B20: AUT | C20: GDP growth (annual %) | D20: NY.GDP.MKTP.KD.ZG | F20: 5.537979 | G20: 2.6486746 | H20: 4.1382678 | I20: 6.1243535 | J20: 3.4801745 | K20: 5.6428614 | L20: 3.0080474 | M20: 4.4723124 | N20: 6.275867 | O20: 7.1228757 | P20: 5.1149684 | Q20: 6.2078606 | R20: 4.890436 | S20: 3.9421382 | T20: -0.36373578 | U20: 4.5784449 | V20: 5.0799812 | W20: -0.21065365 | X20: 5.3566999 | Y20: 1.7314855 | Z20: -0.14429473 | AA20: 2.0112546 | AB20: 2.9730878 | AC20: 0.051275157 | AD20: 2.4986788 | AE20: 2.3013928 | AF20: 1.357168 | AG20: 3.2958798 | AH20: 3.8870748 | AI20: 4.3456418 | AJ20: 3.4416275 | AK20: 2.0935244 | AL20: 0.52680977 | AM20: 2.4021184 | AN20: 2.6679839 | AO20: 2.2157671 | AP20: 2.1458351 | AQ20: 3.49288 | AR20: 3.7619244 | AS20: 3.1895229 | AT20: 1.3169875 | AU20: 1.4843688 | AV20: 1.141565 | AW20: 2.5652553 | AX20: 2.3203651 | AY20: 3.269336 | AZ20: 3.7752247 | BA20: 1.4533056 | BB20: -3.5862647 | BC20: 1.8089824 | BD20: 2.927468 | BE20: 0.62824624 | BF20: -0.25072642 | BG20: 0.75579885 | BH20: 1.3035233 | BI20: 2.1172196 | BJ20: 2.2722499 | BK20: 2.4842211 | BL20: 1.7549762 | BM20: -6.3182551 | BN20: 4.9230917 | BO20: 5.3309638 | BP20: -0.78624429 | BQ20: -0.65908957 | BR20: 0.61574728
A21: Azerbaijan | B21: AZE | C21: GDP growth (annual %) | D21: NY.GDP.MKTP.KD.ZG | AJ21: -0.70000018 | AK21: -22.6 | AL21: -23.099999 | AM21: -19.700001 | AN21: -11.799999 | AO21: 1.2999994 | AP21: 5.8000001 | AQ21: 9.9999996 | AR21: 7.4000013 | AS21: 11.099999 | AT21: 9.8999999 | AU21: 9.4389163 | AV21: 10.208299 | AW21: 9.2538018 | AX21: 27.961538 | AY21: 34.46621 | AZ21: 25.463216 | BA21: 10.591437 | BB21: 9.3695026 | BC21: 4.7888325 | BD21: -1.5729974 | BE21: 2.2029389 | BF21: 5.8434159 | BG21: 2.7975852 | BH21: 1.0495464 | BI21: -3.0635984 | BJ21: 0.15361466 | BK21: 1.5004017 | BL21: 2.4798088 | BM21: -4.1989607 | BN21: 5.6164403 | BO21: 4.7146803 | BP21: 1.3544775 | BQ21: 4.158068 | BR21: 1.4498559
A22: Burundi | B22: BDI | C22: GDP growth (annual %) | D22: NY.GDP.MKTP.KD.ZG | F22: -13.746135 | G22: 9.0631579 | H22: 4.1354074 | I22: 6.2730379 | J22: 3.9672256 | K22: 4.6129929 | L22: 13.821519 | M22: -0.29788367 | N22: -1.4595411 | O22: 21.325671 | P22: 2.7468287 | Q22: -6.4039649 | R22: 6.8890507 | S22: -0.72683956 | T22: 0.69792024 | U22: 7.942661 | V22: 11.469453 | W22: -0.94057599 | X22: 1.664955 | Y22: 0.99105573 | Z22: 12.163276 | AA22: -1.0535998 | AB22: 3.715327 | AC22: 0.155544 | AD22: 11.78318 | AE22: 3.2501805 | AF22: 5.5030961 | AG22: 5.0310244 | AH22: 1.3495022 | AI22: 3.4998221 | AJ22: 4.9968364 | AK22: 1.0099984 | AL22: -6.24 | AM22: -3.83 | AN22: -7.92 | AO22: -8 | AP22: -1.59 | AQ22: 4.75 | AR22: -1.01 | AS22: -0.85686406 | AT22: 2.0558071 | AU22: 4.4465194 | AV22: -1.223728 | AW22: 4.8336578 | AX22: 0.9 | AY22: 5.4138071 | AZ22: 3.4444936 | BA22: 4.9087419 | BB22: 3.7870758 | BC22: 5.093737 | BD22: 4.0244279 | BE22: 4.4230312 | BF22: 4.9239249 | BG22: 4.244908 | BH22: -0.4045256 | BI22: 3.2001747 | BJ22: 3.8318576 | BK22: 5.3422447 | BL22: 4.459342 | BM22: 0.30644381 | BN22: 3.2370748 | BO22: 2.3177012 | BP22: 3.254769 | BQ22: 4.1122738 | BR22: 4.2401053
A23: Belgium | B23: BEL | C23: GDP growth (annual %) | D23: NY.GDP.MKTP.KD.ZG | F23: 4.9784229 | G23: 5.2120032 | H23: 4.3515844 | I23: 6.956685 | J23: 3.5606602 | K23: 3.1558949 | L23: 3.8681472 | M23: 4.1941294 | N23: 6.6298001 | O23: 6.3526723 | P23: 3.9858272 | Q23: 5.2956047 | R23: 6.3817018 | S23: 4.5652585 | T23: -1.9659419 | U23: 5.6527461 | V23: 0.62615457 | W23: 2.8418968 | X23: 2.341073 | Y23: 4.4440539 | Z23: -0.27928359 | AA23: 0.59498677 | AB23: 0.31184301 | AC23: 2.4663825 | AD23: 1.651793 | AE23: 1.822762 | AF23: 2.3066597 | AG23: 4.7232087 | AH23: 3.469167 | AI23: 3.1374022 | AJ23: 1.8330744 | AK23: 1.5306548 | AL23: -0.96187308 | AM23: 3.2269715 | AN23: 2.3847572 | AO23: 1.3214321 | AP23: 3.7936717 | AQ23: 1.9618324 | AR23: 3.542718 | AS23: 3.7167051 | AT23: 1.0996036 | AU23: 1.7068943 | AV23: 1.0379552 | AW23: 3.5712067 | AX23: 2.3217379 | AY23: 2.5523409 | AZ23: 3.6769246 | BA23: 0.44690513 | BB23: -1.9064411 | BC23: 2.7103115 | BD23: 1.931155 | BE23: 0.21580361 | BF23: 0.30549455 | BG23: 1.7655404 | BH23: 1.4741643 | BI23: 1.1935027 | BJ23: 1.4744676 | BK23: 1.8779685 | BL23: 2.44289 | BM23: -4.7929839 | BN23: 6.2544569 | BO23: 4.0246085 | BP23: 1.5612554 | BQ23: 1.0977538 | BR23: 0.98311797
A24: Benin | B24: BEN | C24: GDP growth (annual %) | D24: NY.GDP.MKTP.KD.ZG | F24: 3.1412805 | G24: -3.4264098 | H24: 4.730028 | I24: 6.6507591 | J24: 5.2938628 | K24: 3.5758627 | L24: 1.0783987 | M24: 3.8423356 | N24: 2.877498 | O24: 2.0977576 | P24: -1.4968418 | Q24: 6.4263675 | R24: 3.7061653 | S24: 3.3393122 | T24: -4.8953454 | U24: 0.88435633 | V24: 4.9836637 | W24: 1.255078 | X24: 6.5357474 | Y24: 6.7817639 | Z24: 9.9542312 | AA24: 2.2350663 | AB24: -4.3478227 | AC24: 7.9298396 | AD24: 7.5303248 | AE24: 2.1711416 | AF24: -1.500003 | AG24: 3.4052453 | AH24: -2.8541605 | AI24: 8.9761344 | AJ24: 4.2257994 | AK24: 2.9577108 | AL24: 5.8361721 | AM24: 2.0204004 | AN24: 6.0451987 | AO24: 4.324284 | AP24: 5.7346884 | AQ24: 3.9610121 | AR24: 5.3414494 | AS24: 5.8577142 | AT24: 5.3331357 | AU24: 4.6430309 | AV24: 3.4435768 | AW24: 4.4296846 | AX24: 1.7131646 | AY24: 3.9437388 | AZ24: 5.9863493 | BA24: 4.8965771 | BB24: 2.3192921 | BC24: 2.1140647 | BD24: 2.9637529 | BE24: 4.8112233 | BF24: 7.1914337 | BG24: 6.3576791 | BH24: 1.7781511 | BI24: 3.3396734 | BJ24: 5.671562 | BK24: 6.6972536 | BL24: 6.8656866 | BM24: 3.8487924 | BN24: 7.1554516 | BO24: 6.2529471 | BP24: 6.3527774 | BQ24: 7.4531157 | BR24: 8.0740845
A25: Burkina Faso | B25: BFA | C25: GDP growth (annual %) | D25: NY.GDP.MKTP.KD.ZG | F25: 4.043928 | G25: 6.1287988 | H25: -1.2680164 | I25: 2.2828192 | J25: 3.7645454 | K25: 0.53761308 | L25: 8.823315 | M25: 3.0707739 | N25: 2.026081 | O25: 0.11701961 | P25: 1.4133399 | Q25: 2.3114987 | R25: 0.4493274 | S25: 8.2864265 | T25: 2.9983829 | U25: 8.534895 | V25: 0.37035356 | W25: 4.607825 | X25: 3.6646215 | Y25: 0.79687888 | Z25: 4.2553034 | AA25: 9.5621966 | AB25: 0.34598474 | AC25: -1.7786967 | AD25: 8.517365 | AE25: 7.9553627 | AF25: -0.23633679 | AG25: 5.795593 | AH25: 2.1502673 | AI25: -0.60292848 | AJ25: 9.0699845 | AK25: 0.23271076 | AL25: 3.4613849 | AM25: 1.3150073 | AN25: 5.7163739 | AO25: 11.014744 | AP25: 6.3168347 | AQ25: 7.3077196 | AR25: 7.3952378 | AS25: 1.8884739 | AT25: 6.6134057 | AU25: 4.3529638 | AV25: 7.8024939 | AW25: 4.4784521 | AX25: 8.6618732 | AY25: 6.2531647 | AZ25: 4.111379 | BA25: 5.7999917 | BB25: 2.9619509 | BC25: 8.4462816 | BD25: 6.6225626 | BE25: 6.4526724 | BF25: 5.7925848 | BG25: 4.3268456 | BH25: 3.9212288 | BI25: 5.9579767 | BJ25: 6.2034894 | BK25: 6.6045691 | BL25: 5.889205 | BM25: 2.0107726 | BN25: 6.9425249 | BO25: 1.6267326 | BP25: 3.0002742 | BQ25: 4.8339581 | BR25: 5.2946184
A26: Bangladesh | B26: BGD | C26: GDP growth (annual %) | D26: NY.GDP.MKTP.KD.ZG | F26: 6.0581608 | G26: 5.453031 | H26: -0.45589429 | I26: 10.952789 | J26: 1.6062582 | K26: 2.566812 | L26: -1.8758639 | M26: 9.489454 | N26: 1.2208579 | O26: 5.6198523 | P26: -5.479483 | Q26: -13.973729 | R26: 3.3256802 | S26: 9.5919563 | T26: -4.0882141 | U26: 5.6613612 | V26: 2.6730561 | W26: 7.0738377 | X26: 4.8016346 | Y26: 0.81914187 | Z26: 7.2339437 | AA26: 2.1343278 | AB26: 3.8810464 | AC26: 4.80331 | AD26: 3.3420147 | AE26: 4.1733826 | AF26: 3.7724019 | AG26: 2.4162569 | AH26: 2.8365821 | AI26: 5.6222582 | AJ26: 3.4852278 | AK26: 5.4426855 | AL26: 4.7115617 | AM26: 3.8901264 | AN26: 5.1212779 | AO26: 4.5229192 | AP26: 4.4898965 | AQ26: 5.1770269 | AR26: 4.6701564 | AS26: 5.2932947 | AT26: 5.0772878 | AU26: 3.8331239 | AV26: 4.7395674 | AW26: 5.2395329 | AX26: 6.5359449 | AY26: 6.671905 | AZ26: 7.0585994 | BA26: 6.0137898 | BB26: 5.0451248 | BC26: 5.5717882 | BD26: 6.4643791 | BE26: 6.5214588 | BF26: 6.0136057 | BG26: 6.0610594 | BH26: 6.5526399 | BI26: 7.1134782 | BJ26: 6.59025 | BK26: 7.3194126 | BL26: 7.8819152 | BM26: 3.4480176 | BN26: 6.9386791 | BO26: 7.0998288 | BP26: 5.7751124 | BQ26: 4.2232591 | BR26: 3.4899067
A27: Bulgaria | B27: BGR | C27: GDP growth (annual %) | D27: NY.GDP.MKTP.KD.ZG | Z27: 4.9001637 | AA27: 2.3345645 | AB27: 3.4303075 | AC27: 3.3964432 | AD27: 2.6834386 | AE27: 4.2076027 | AF27: 6.0545144 | AG27: 10.944692 | AH27: -3.2898823 | AI27: -9.1173762 | AJ27: -8.4453556 | AK27: -7.2723874 | AL27: -1.4802147 | AM27: 1.8180119 | AN27: 2.9023154 | AO27: 5.2054792 | AP27: -14.115377 | AQ27: 3.7891145 | AR27: -8.3960877 | AS27: 4.5872255 | AT27: 3.8237022 | AU27: 5.8719313 | AV27: 5.2371528 | AW27: 6.5104241 | AX27: 7.0563492 | AY27: 6.8025926 | AZ27: 6.6543851 | BA27: 6.1295589 | BB27: -3.3471431 | BC27: 1.5553627 | BD27: 2.090176 | BE27: 0.74881456 | BF27: -0.5427534 | BG27: 0.94944977 | BH27: 3.3975535 | BI27: 3.0266282 | BJ27: 2.7459274 | BK27: 2.3301505 | BL27: 3.7933196 | BM27: -3.1332354 | BN27: 7.8281731 | BO27: 4.083864 | BP27: 1.6815108 | BQ27: 3.3870896 | BR27: 3.0963664
A28: Bahrain | B28: BHR | C28: GDP growth (annual %) | D28: NY.GDP.MKTP.KD.ZG | P28: 1.6071429 | Q28: 11.072056 | R28: 13.924051 | S28: 8.4722222 | T28: -8.8348272 | U28: 30.476297 | V28: 13.01765 | W28: 3.8622686 | X28: 3.469268 | Y28: 2.5802793 | Z28: -5.3166974 | AA28: -7.5562177 | AB28: 6.3763768 | AC28: 5.003646 | AD28: -4.7582685 | AE28: 1.1829939 | AF28: 10.399009 | AG28: 6.9999916 | AH28: 0.36400714 | AI28: 4.4379972 | AJ28: 11.229998 | AK28: 6.6899981 | AL28: 12.870007 | AM28: -0.25000138 | AN28: 3.9299924 | AO28: 4.1100063 | AP28: 3.0929992 | AQ28: 4.7900036 | AR28: 4.2999982 | AS28: 5.3000694 | AT28: 2.4909488 | AU28: 3.3485507 | AV28: 6.2964413 | AW28: 6.9809618 | AX28: 6.7689974 | AY28: 6.4669995 | AZ28: 8.2939613 | BA28: 6.2450109 | BB28: 2.5398857 | BC28: 4.334299 | BD28: 1.9281579 | BE28: 3.803029 | BF28: 5.2926222 | BG28: 4.3088569 | BH28: 2.5078721 | BI28: 3.8149933 | BJ28: 4.9538353 | BK28: 2.0525886 | BL28: 2.0528777 | BM28: -5.911363 | BN28: 4.3500409 | BO28: 6.1801613 | BP28: 3.8781161 | BQ28: 2.8971054 | BR28: 3.4813757
A29: Bahamas, The | B29: BHS | C29: GDP growth (annual %) | D29: NY.GDP.MKTP.KD.ZG | F29: 10.667097 | G29: 10.451972 | H29: 10.524055 | I29: 10.501567 | J29: 10.425596 | K29: 9.0719287 | L29: 9.5981139 | M29: 8.4217636 | N29: 8.9816626 | O29: -5.6496495 | P29: 1.6265087 | Q29: -3.4973359 | R29: 7.5675688 | S29: -16.754229 | T29: -14.803126 | U29: 5.185185 | V29: 9.1549292 | W29: 14.17952 | X29: 26.139296 | Y29: 6.4952819 | Z29: -9.2264051 | AA29: 6.6988977 | AB29: 3.5970519 | AC29: 14.171149 | AD29: 4.8291801 | AE29: 1.7970002 | AF29: 2.9845193 | AG29: 2.3097077 | AH29: 6.7273298 | AI29: -1.5962491 | AJ29: -4.181785 | AK29: -3.8255823 | AL29: 0.3078066 | AM29: 3.148916 | AN29: 4.378752 | AO29: 4.2235304 | AP29: 1.2877532 | AQ29: 4.7167986 | AR29: 7.1441039 | AS29: 4.1484193 | AT29: 2.6260098 | AU29: 2.7049562 | AV29: -1.2649167 | AW29: 0.88237374 | AX29: 3.3960842 | AY29: 2.5165922 | AZ29: 1.4460999 | BA29: -2.3236481 | BB29: -4.1754281 | BC29: 1.5386625 | BD29: 0.61317074 | BE29: 4.5200389 | BF29: -2.8632008 | BG29: 1.8469701 | BH29: 0.99741168 | BI29: -1.1565081 | BJ29: 3.3713988 | BK29: 2.3979551 | BL29: -0.83858587 | BM29: -20.089366 | BN29: 17.586139 | BO29: 10.877901 | BP29: 3.0482418 | BQ29: 3.3786655
A30: Bosnia and Herzegovina | B30: BIH | C30: GDP growth (annual %) | D30: NY.GDP.MKTP.KD.ZG | AJ30: -9.3480254 | AK30: -6.4369076 | AL30: -2.1813473 | AM30: 11.131964 | AN30: 15.968301 | AO30: 54.1993 | AP30: 36.641129 | AQ30: 16.616375 | AR30: 9.52157 | AS30: 5.414316 | AT30: 2.4233131 | AU30: 5.0274446 | AV30: 3.8671355 | AW30: 6.3252679 | AX30: 3.8971832 | AY30: 5.414003 | AZ30: 5.8591169 | BA30: 5.4418473 | BB30: -3.0044555 | BC30: 0.86566724 | BD30: 0.95951171 | BE30: -0.82183725 | BF30: 2.3498587 | BG30: 1.1538479 | BH30: 4.2841302 | BI30: 3.2422582 | BJ30: 3.244099 | BK30: 3.829004 | BL30: 2.8858524 | BM30: -3.0150934 | BN30: 7.3916426 | BO30: 4.2268133 | BP30: 1.9943941 | BQ30: 3.2267998 | BR30: 2.1286191
A31: Belarus | B31: BLR | C31: GDP growth (annual %) | D31: NY.GDP.MKTP.KD.ZG | AJ31: -1.1999957 | AK31: -9.6000011 | AL31: -7.600002 | AM31: -11.700004 | AN31: -10.4 | AO31: 2.8000046 | AP31: 11.400005 | AQ31: 8.3999914 | AR31: 3.3999992 | AS31: 5.8000033 | AT31: 4.7253061 | AU31: 5.0452676 | AV31: 7.0431925 | AW31: 11.449743 | AX31: 9.4000015 | AY31: 9.9999947 | AZ31: 8.6000066 | BA31: 10.199999 | BB31: 0.19999523 | BC31: 7.7500171 | BD31: 5.5499747 | BE31: 1.7078525 | BF31: 0.9987193 | BG31: 1.6511247 | BH31: -3.8295706 | BI31: -2.5264464 | BJ31: 2.5321835 | BK31: 3.1491976 | BL31: 1.4464555 | BM31: -0.67274292 | BN31: 2.4388621 | BO31: -4.6583959 | BP31: 4.1265401 | BQ31: 4.3499964 | BR31: 1.3
A32: Belize | B32: BLZ | C32: GDP growth (annual %) | D32: NY.GDP.MKTP.KD.ZG | F32: 4.892277 | G32: 4.8926523 | H32: 4.9564342 | I32: 4.9998798 | J32: 4.930541 | K32: 4.7708452 | L32: 4.9131232 | M32: 7.3672255 | N32: 5.1063747 | O32: 4.8076934 | P32: 3.9594411 | Q32: 10.218304 | R32: 5.3518941 | S32: 13.559985 | T32: 3.5928244 | U32: -0.034020934 | V32: 6.4965944 | W32: 7.9208072 | X32: 7.5170214 | Y32: 12.10875 | Z32: 1.1332974 | AA32: -0.10672359 | AB32: -2.1474359 | AC32: 1.9761983 | AD32: 1.006424 | AE32: 4.5473818 | AF32: 10.726959 | AG32: 9.7884809 | AH32: 13.010842 | AI32: 11.342943 | AJ32: 11.778703 | AK32: 12.736223 | AL32: 6.1378854 | AM32: -0.019986339 | AN32: 0.73155801 | AO32: 1.1053058 | AP32: 4.2346159 | AQ32: 3.89302 | AR32: 9.4231947 | AS32: 12.240612 | AT32: 4.9935621 | AU32: 5.3990732 | AV32: 9.6652268 | AW32: 4.7806651 | AX32: 2.2191905 | AY32: 4.5114546 | AZ32: 3.3393974 | BA32: -1.6274778 | BB32: -0.44670964 | BC32: 1.417411 | BD32: -0.13007112 | BE32: 3.9438932 | BF32: 4.0664656 | BG32: 3.8922607 | BH32: 2.7602603 | BI32: -0.018741496 | BJ32: -1.8332373 | BK32: 0.82206859 | BL32: 4.2565871 | BM32: -13.5229 | BN32: 17.989924 | BO32: 9.2505133 | BP32: 0.50012794 | BQ32: 3.5046644 | BR32: 2.7483173
